[2025-04-07T17:01:53.185+0000] {local_task_job_runner.py:123} INFO - ::group::Pre task execution logs
[2025-04-07T17:01:53.286+0000] {taskinstance.py:2614} INFO - Dependencies all met for dep_context=non-requeueable deps ti=<TaskInstance: scrape_amazon_dag.process_Automotive_Enthusiast_Merchandise_13 manual__2025-04-07T17:01:09.892232+00:00 [queued]>
[2025-04-07T17:01:53.321+0000] {taskinstance.py:2614} INFO - Dependencies all met for dep_context=requeueable deps ti=<TaskInstance: scrape_amazon_dag.process_Automotive_Enthusiast_Merchandise_13 manual__2025-04-07T17:01:09.892232+00:00 [queued]>
[2025-04-07T17:01:53.336+0000] {taskinstance.py:2867} INFO - Starting attempt 1 of 2
[2025-04-07T17:01:53.414+0000] {taskinstance.py:2890} INFO - Executing <Task(PythonOperator): process_Automotive_Enthusiast_Merchandise_13> on 2025-04-07 17:01:09.892232+00:00
[2025-04-07T17:01:53.442+0000] {warnings.py:112} WARNING - /home/***/.local/lib/python3.12/site-packages/***/task/task_runner/standard_task_runner.py:70: DeprecationWarning: This process (pid=948) is multi-threaded, use of fork() may lead to deadlocks in the child.
  pid = os.fork()

[2025-04-07T17:01:53.449+0000] {standard_task_runner.py:72} INFO - Started process 1080 to run task
[2025-04-07T17:01:53.458+0000] {standard_task_runner.py:104} INFO - Running: ['***', 'tasks', 'run', 'scrape_amazon_dag', 'process_Automotive_Enthusiast_Merchandise_13', 'manual__2025-04-07T17:01:09.892232+00:00', '--job-id', '83', '--raw', '--subdir', 'DAGS_FOLDER/test_crawl_list_product.py', '--cfg-path', '/tmp/tmp6x2t_a0c']
[2025-04-07T17:01:53.466+0000] {standard_task_runner.py:105} INFO - Job 83: Subtask process_Automotive_Enthusiast_Merchandise_13
[2025-04-07T17:01:55.716+0000] {task_command.py:467} INFO - Running <TaskInstance: scrape_amazon_dag.process_Automotive_Enthusiast_Merchandise_13 manual__2025-04-07T17:01:09.892232+00:00 [running]> on host 13b4251b7529
[2025-04-07T17:01:58.386+0000] {taskinstance.py:3134} INFO - Exporting env vars: AIRFLOW_CTX_DAG_OWNER='***' AIRFLOW_CTX_DAG_ID='scrape_amazon_dag' AIRFLOW_CTX_TASK_ID='process_Automotive_Enthusiast_Merchandise_13' AIRFLOW_CTX_EXECUTION_DATE='2025-04-07T17:01:09.892232+00:00' AIRFLOW_CTX_TRY_NUMBER='1' AIRFLOW_CTX_DAG_RUN_ID='manual__2025-04-07T17:01:09.892232+00:00'
[2025-04-07T17:01:58.390+0000] {logging_mixin.py:190} INFO - Task instance is in running state
[2025-04-07T17:01:58.399+0000] {logging_mixin.py:190} INFO -  Previous state of the Task instance: queued
[2025-04-07T17:01:58.400+0000] {logging_mixin.py:190} INFO - Current task name:process_Automotive_Enthusiast_Merchandise_13 state:running start_date:2025-04-07 17:01:53.287502+00:00
[2025-04-07T17:01:58.401+0000] {logging_mixin.py:190} INFO - Dag name:scrape_amazon_dag and current dag run status:running
[2025-04-07T17:01:58.402+0000] {taskinstance.py:732} INFO - ::endgroup::
[2025-04-07T17:01:58.403+0000] {test_crawl_list_product.py:227} INFO - Processing: Automotive/Automotive Enthusiast Merchandise - https://www.amazon.com/s?bbn=2562090011&rh=i%3Aspecialty-aps%2Cn%3A2562090011%2Cn%3A%2115690151%2Cn%3A2204830011&s=date-desc-rank&ref_=nav_em__nav_desktop_sa_intl_automotive_enthusiast_merchandise_0_2_10_15
[2025-04-07T17:01:59.527+0000] {logger.py:11} INFO - ====== WebDriver manager ======
[2025-04-07T17:02:01.801+0000] {job.py:229} INFO - Heartbeat recovered after 10.61 seconds
[2025-04-07T17:02:08.017+0000] {logger.py:11} INFO - Get LATEST chromedriver version for google-chrome
[2025-04-07T17:02:08.241+0000] {logger.py:11} INFO - Get LATEST chromedriver version for google-chrome
[2025-04-07T17:02:08.424+0000] {logger.py:11} INFO - Driver [/home/***/.wdm/drivers/chromedriver/linux64/135.0.7049.42/chromedriver-linux64/chromedriver] found in cache
[2025-04-07T17:02:29.090+0000] {job.py:229} INFO - Heartbeat recovered after 11.03 seconds
[2025-04-07T17:05:06.538+0000] {test_crawl_list_product.py:220} ERROR - Error during scraping https://www.amazon.com/s?bbn=2562090011&rh=i%3Aspecialty-aps%2Cn%3A2562090011%2Cn%3A%2115690151%2Cn%3A2204830011&s=date-desc-rank&ref_=nav_em__nav_desktop_sa_intl_automotive_enthusiast_merchandise_0_2_10_15: HTTPConnectionPool(host='localhost', port=54529): Read timed out. (read timeout=120)
[2025-04-07T17:02:57.371+0000] {job.py:239} ERROR - Job heartbeat failed with error
Traceback (most recent call last):
  File "/home/airflow/.local/lib/python3.12/site-packages/sqlalchemy/engine/base.py", line 3371, in _wrap_pool_connect
    return fn()
           ^^^^
  File "/home/airflow/.local/lib/python3.12/site-packages/sqlalchemy/pool/base.py", line 327, in connect
    return _ConnectionFairy._checkout(self)
           ^^^^^^^^^^^^^^^^^^^^^^^^^^^^^^^^
  File "/home/airflow/.local/lib/python3.12/site-packages/sqlalchemy/pool/base.py", line 894, in _checkout
    fairy = _ConnectionRecord.checkout(pool)
            ^^^^^^^^^^^^^^^^^^^^^^^^^^^^^^^^
  File "/home/airflow/.local/lib/python3.12/site-packages/sqlalchemy/pool/base.py", line 493, in checkout
    rec = pool._do_get()
          ^^^^^^^^^^^^^^
  File "/home/airflow/.local/lib/python3.12/site-packages/sqlalchemy/pool/impl.py", line 256, in _do_get
    return self._create_connection()
           ^^^^^^^^^^^^^^^^^^^^^^^^^
  File "/home/airflow/.local/lib/python3.12/site-packages/sqlalchemy/pool/base.py", line 273, in _create_connection
    return _ConnectionRecord(self)
           ^^^^^^^^^^^^^^^^^^^^^^^
  File "/home/airflow/.local/lib/python3.12/site-packages/sqlalchemy/pool/base.py", line 388, in __init__
    self.__connect()
  File "/home/airflow/.local/lib/python3.12/site-packages/sqlalchemy/pool/base.py", line 690, in __connect
    with util.safe_reraise():
         ^^^^^^^^^^^^^^^^^^^
  File "/home/airflow/.local/lib/python3.12/site-packages/sqlalchemy/util/langhelpers.py", line 70, in __exit__
    compat.raise_(
  File "/home/airflow/.local/lib/python3.12/site-packages/sqlalchemy/util/compat.py", line 211, in raise_
    raise exception
  File "/home/airflow/.local/lib/python3.12/site-packages/sqlalchemy/pool/base.py", line 686, in __connect
    self.dbapi_connection = connection = pool._invoke_creator(self)
                                         ^^^^^^^^^^^^^^^^^^^^^^^^^^
  File "/home/airflow/.local/lib/python3.12/site-packages/sqlalchemy/engine/create.py", line 574, in connect
    return dialect.connect(*cargs, **cparams)
           ^^^^^^^^^^^^^^^^^^^^^^^^^^^^^^^^^^
  File "/home/airflow/.local/lib/python3.12/site-packages/sqlalchemy/engine/default.py", line 598, in connect
    return self.dbapi.connect(*cargs, **cparams)
           ^^^^^^^^^^^^^^^^^^^^^^^^^^^^^^^^^^^^^
  File "/home/airflow/.local/lib/python3.12/site-packages/psycopg2/__init__.py", line 122, in connect
    conn = _connect(dsn, connection_factory=connection_factory, **kwasync)
           ^^^^^^^^^^^^^^^^^^^^^^^^^^^^^^^^^^^^^^^^^^^^^^^^^^^^^^^^^^^^^^^
psycopg2.OperationalError: could not translate host name "postgres" to address: Temporary failure in name resolution


The above exception was the direct cause of the following exception:

Traceback (most recent call last):
  File "/home/airflow/.local/lib/python3.12/site-packages/airflow/jobs/job.py", line 233, in heartbeat
    heartbeat_callback(session)
  File "/home/airflow/.local/lib/python3.12/site-packages/airflow/utils/session.py", line 94, in wrapper
    return func(*args, **kwargs)
           ^^^^^^^^^^^^^^^^^^^^^
  File "/home/airflow/.local/lib/python3.12/site-packages/airflow/jobs/local_task_job_runner.py", line 284, in heartbeat_callback
    self.task_instance.refresh_from_db()
  File "/home/airflow/.local/lib/python3.12/site-packages/airflow/utils/session.py", line 97, in wrapper
    return func(*args, session=session, **kwargs)
           ^^^^^^^^^^^^^^^^^^^^^^^^^^^^^^^^^^^^^^
  File "/home/airflow/.local/lib/python3.12/site-packages/airflow/models/taskinstance.py", line 2360, in refresh_from_db
    _refresh_from_db(task_instance=self, session=session, lock_for_update=lock_for_update)
  File "/home/airflow/.local/lib/python3.12/site-packages/airflow/models/taskinstance.py", line 873, in _refresh_from_db
    ti = TaskInstance.get_task_instance(
         ^^^^^^^^^^^^^^^^^^^^^^^^^^^^^^^
  File "/home/airflow/.local/lib/python3.12/site-packages/airflow/api_internal/internal_api_call.py", line 166, in wrapper
    return func(*args, **kwargs)
           ^^^^^^^^^^^^^^^^^^^^^
  File "/home/airflow/.local/lib/python3.12/site-packages/airflow/utils/session.py", line 94, in wrapper
    return func(*args, **kwargs)
           ^^^^^^^^^^^^^^^^^^^^^
  File "/home/airflow/.local/lib/python3.12/site-packages/airflow/models/taskinstance.py", line 2346, in get_task_instance
    return query.one_or_none()
           ^^^^^^^^^^^^^^^^^^^
  File "/home/airflow/.local/lib/python3.12/site-packages/sqlalchemy/orm/query.py", line 2850, in one_or_none
    return self._iter().one_or_none()
           ^^^^^^^^^^^^
  File "/home/airflow/.local/lib/python3.12/site-packages/sqlalchemy/orm/query.py", line 2916, in _iter
    result = self.session.execute(
             ^^^^^^^^^^^^^^^^^^^^^
  File "/home/airflow/.local/lib/python3.12/site-packages/sqlalchemy/orm/session.py", line 1716, in execute
    conn = self._connection_for_bind(bind)
           ^^^^^^^^^^^^^^^^^^^^^^^^^^^^^^^
  File "/home/airflow/.local/lib/python3.12/site-packages/sqlalchemy/orm/session.py", line 1555, in _connection_for_bind
    return self._transaction._connection_for_bind(
           ^^^^^^^^^^^^^^^^^^^^^^^^^^^^^^^^^^^^^^^
  File "/home/airflow/.local/lib/python3.12/site-packages/sqlalchemy/orm/session.py", line 750, in _connection_for_bind
    conn = bind.connect()
           ^^^^^^^^^^^^^^
  File "/home/airflow/.local/lib/python3.12/site-packages/sqlalchemy/future/engine.py", line 412, in connect
    return super(Engine, self).connect()
           ^^^^^^^^^^^^^^^^^^^^^^^^^^^^^
  File "/home/airflow/.local/lib/python3.12/site-packages/sqlalchemy/engine/base.py", line 3325, in connect
    return self._connection_cls(self, close_with_result=close_with_result)
           ^^^^^^^^^^^^^^^^^^^^^^^^^^^^^^^^^^^^^^^^^^^^^^^^^^^^^^^^^^^^^^^
  File "/home/airflow/.local/lib/python3.12/site-packages/sqlalchemy/engine/base.py", line 96, in __init__
    else engine.raw_connection()
         ^^^^^^^^^^^^^^^^^^^^^^^
  File "/home/airflow/.local/lib/python3.12/site-packages/sqlalchemy/engine/base.py", line 3404, in raw_connection
    return self._wrap_pool_connect(self.pool.connect, _connection)
           ^^^^^^^^^^^^^^^^^^^^^^^^^^^^^^^^^^^^^^^^^^^^^^^^^^^^^^^
  File "/home/airflow/.local/lib/python3.12/site-packages/sqlalchemy/engine/base.py", line 3374, in _wrap_pool_connect
    Connection._handle_dbapi_exception_noconnection(
  File "/home/airflow/.local/lib/python3.12/site-packages/sqlalchemy/engine/base.py", line 2208, in _handle_dbapi_exception_noconnection
    util.raise_(
  File "/home/airflow/.local/lib/python3.12/site-packages/sqlalchemy/util/compat.py", line 211, in raise_
    raise exception
  File "/home/airflow/.local/lib/python3.12/site-packages/sqlalchemy/engine/base.py", line 3371, in _wrap_pool_connect
    return fn()
           ^^^^
  File "/home/airflow/.local/lib/python3.12/site-packages/sqlalchemy/pool/base.py", line 327, in connect
    return _ConnectionFairy._checkout(self)
           ^^^^^^^^^^^^^^^^^^^^^^^^^^^^^^^^
  File "/home/airflow/.local/lib/python3.12/site-packages/sqlalchemy/pool/base.py", line 894, in _checkout
    fairy = _ConnectionRecord.checkout(pool)
            ^^^^^^^^^^^^^^^^^^^^^^^^^^^^^^^^
  File "/home/airflow/.local/lib/python3.12/site-packages/sqlalchemy/pool/base.py", line 493, in checkout
    rec = pool._do_get()
          ^^^^^^^^^^^^^^
  File "/home/airflow/.local/lib/python3.12/site-packages/sqlalchemy/pool/impl.py", line 256, in _do_get
    return self._create_connection()
           ^^^^^^^^^^^^^^^^^^^^^^^^^
  File "/home/airflow/.local/lib/python3.12/site-packages/sqlalchemy/pool/base.py", line 273, in _create_connection
    return _ConnectionRecord(self)
           ^^^^^^^^^^^^^^^^^^^^^^^
  File "/home/airflow/.local/lib/python3.12/site-packages/sqlalchemy/pool/base.py", line 388, in __init__
    self.__connect()
  File "/home/airflow/.local/lib/python3.12/site-packages/sqlalchemy/pool/base.py", line 690, in __connect
    with util.safe_reraise():
         ^^^^^^^^^^^^^^^^^^^
  File "/home/airflow/.local/lib/python3.12/site-packages/sqlalchemy/util/langhelpers.py", line 70, in __exit__
    compat.raise_(
  File "/home/airflow/.local/lib/python3.12/site-packages/sqlalchemy/util/compat.py", line 211, in raise_
    raise exception
  File "/home/airflow/.local/lib/python3.12/site-packages/sqlalchemy/pool/base.py", line 686, in __connect
    self.dbapi_connection = connection = pool._invoke_creator(self)
                                         ^^^^^^^^^^^^^^^^^^^^^^^^^^
  File "/home/airflow/.local/lib/python3.12/site-packages/sqlalchemy/engine/create.py", line 574, in connect
    return dialect.connect(*cargs, **cparams)
           ^^^^^^^^^^^^^^^^^^^^^^^^^^^^^^^^^^
  File "/home/airflow/.local/lib/python3.12/site-packages/sqlalchemy/engine/default.py", line 598, in connect
    return self.dbapi.connect(*cargs, **cparams)
           ^^^^^^^^^^^^^^^^^^^^^^^^^^^^^^^^^^^^^
  File "/home/airflow/.local/lib/python3.12/site-packages/psycopg2/__init__.py", line 122, in connect
    conn = _connect(dsn, connection_factory=connection_factory, **kwasync)
           ^^^^^^^^^^^^^^^^^^^^^^^^^^^^^^^^^^^^^^^^^^^^^^^^^^^^^^^^^^^^^^^
sqlalchemy.exc.OperationalError: (psycopg2.OperationalError) could not translate host name "postgres" to address: Temporary failure in name resolution

(Background on this error at: https://sqlalche.me/e/14/e3q8)
[2025-04-07T17:05:59.239+0000] {job.py:254} ERROR - Job heartbeat failed with error. Scheduler is in unhealthy state
[2025-04-07T17:05:59.392+0000] {test_crawl_list_product.py:191} INFO - Saved/Updated 0 products to /opt/***/csv/src_output/pt1_20250407/part1_data_Automotive_Automotive Enthusiast Merchandise_20250407.csv
[2025-04-07T17:06:18.864+0000] {job.py:229} INFO - Heartbeat recovered after 211.61 seconds
[2025-04-07T17:07:44.045+0000] {python.py:240} INFO - Done. Returned value was: None
[2025-04-07T17:07:44.549+0000] {taskinstance.py:341} INFO - ::group::Post task execution logs
[2025-04-07T17:07:44.550+0000] {taskinstance.py:353} INFO - Marking task as SUCCESS. dag_id=scrape_amazon_dag, task_id=process_Automotive_Enthusiast_Merchandise_13, run_id=manual__2025-04-07T17:01:09.892232+00:00, execution_date=20250407T170109, start_date=20250407T170153, end_date=20250407T170744
[2025-04-07T17:07:50.645+0000] {logging_mixin.py:190} INFO - Task instance in success state
[2025-04-07T17:07:50.646+0000] {logging_mixin.py:190} INFO -  Previous state of the Task instance: running
[2025-04-07T17:07:50.647+0000] {logging_mixin.py:190} INFO - Dag name:scrape_amazon_dag queued_at:2025-04-07 17:01:09.926255+00:00
[2025-04-07T17:07:50.648+0000] {logging_mixin.py:190} INFO - Task hostname:13b4251b7529 operator:PythonOperator
[2025-04-07T17:07:50.706+0000] {local_task_job_runner.py:266} INFO - Task exited with return code 0
[2025-04-07T17:07:50.779+0000] {local_task_job_runner.py:245} INFO - ::endgroup::
[2025-04-23T14:23:55.939+0000] {local_task_job_runner.py:123} INFO - ::group::Pre task execution logs
[2025-04-23T14:23:55.985+0000] {taskinstance.py:2604} INFO - Dependencies not met for <TaskInstance: scrape_amazon_dag.process_Automotive_Enthusiast_Merchandise_13 manual__2025-04-07T17:01:09.892232+00:00 [success]>, dependency 'Task Instance State' FAILED: Task is in the 'success' state.
[2025-04-23T14:23:56.014+0000] {local_task_job_runner.py:166} INFO - Task is not able to be run
