[2025-04-07T17:01:53.214+0000] {local_task_job_runner.py:123} INFO - ::group::Pre task execution logs
[2025-04-07T17:01:53.295+0000] {taskinstance.py:2614} INFO - Dependencies all met for dep_context=non-requeueable deps ti=<TaskInstance: scrape_amazon_dag.process_Tires___Wheels_11 manual__2025-04-07T17:01:09.892232+00:00 [queued]>
[2025-04-07T17:01:53.367+0000] {taskinstance.py:2614} INFO - Dependencies all met for dep_context=requeueable deps ti=<TaskInstance: scrape_amazon_dag.process_Tires___Wheels_11 manual__2025-04-07T17:01:09.892232+00:00 [queued]>
[2025-04-07T17:01:53.368+0000] {taskinstance.py:2867} INFO - Starting attempt 1 of 2
[2025-04-07T17:01:53.552+0000] {taskinstance.py:2890} INFO - Executing <Task(PythonOperator): process_Tires___Wheels_11> on 2025-04-07 17:01:09.892232+00:00
[2025-04-07T17:01:54.194+0000] {warnings.py:112} WARNING - /home/***/.local/lib/python3.12/site-packages/***/task/task_runner/standard_task_runner.py:70: DeprecationWarning: This process (pid=955) is multi-threaded, use of fork() may lead to deadlocks in the child.
  pid = os.fork()

[2025-04-07T17:01:54.196+0000] {standard_task_runner.py:72} INFO - Started process 1089 to run task
[2025-04-07T17:01:54.190+0000] {standard_task_runner.py:104} INFO - Running: ['***', 'tasks', 'run', 'scrape_amazon_dag', 'process_Tires___Wheels_11', 'manual__2025-04-07T17:01:09.892232+00:00', '--job-id', '79', '--raw', '--subdir', 'DAGS_FOLDER/test_crawl_list_product.py', '--cfg-path', '/tmp/tmpjsfl_1n6']
[2025-04-07T17:01:54.853+0000] {standard_task_runner.py:105} INFO - Job 79: Subtask process_Tires___Wheels_11
[2025-04-07T17:01:58.320+0000] {task_command.py:467} INFO - Running <TaskInstance: scrape_amazon_dag.process_Tires___Wheels_11 manual__2025-04-07T17:01:09.892232+00:00 [running]> on host 13b4251b7529
[2025-04-07T17:02:02.228+0000] {job.py:229} INFO - Heartbeat recovered after 10.78 seconds
[2025-04-07T17:02:02.247+0000] {taskinstance.py:3134} INFO - Exporting env vars: AIRFLOW_CTX_DAG_OWNER='***' AIRFLOW_CTX_DAG_ID='scrape_amazon_dag' AIRFLOW_CTX_TASK_ID='process_Tires___Wheels_11' AIRFLOW_CTX_EXECUTION_DATE='2025-04-07T17:01:09.892232+00:00' AIRFLOW_CTX_TRY_NUMBER='1' AIRFLOW_CTX_DAG_RUN_ID='manual__2025-04-07T17:01:09.892232+00:00'
[2025-04-07T17:02:02.268+0000] {logging_mixin.py:190} INFO - Task instance is in running state
[2025-04-07T17:02:02.272+0000] {logging_mixin.py:190} INFO -  Previous state of the Task instance: queued
[2025-04-07T17:02:02.277+0000] {logging_mixin.py:190} INFO - Current task name:process_Tires___Wheels_11 state:running start_date:2025-04-07 17:01:53.302379+00:00
[2025-04-07T17:02:02.278+0000] {logging_mixin.py:190} INFO - Dag name:scrape_amazon_dag and current dag run status:running
[2025-04-07T17:02:02.293+0000] {taskinstance.py:732} INFO - ::endgroup::
[2025-04-07T17:02:02.367+0000] {test_crawl_list_product.py:227} INFO - Processing: Automotive/Tires & Wheels - https://www.amazon.com/s?bbn=2562090011&rh=i%3Aspecialty-aps%2Cn%3A2562090011%2Cn%3A%2115690151%2Cn%3A15706571&s=date-desc-rank&ref_=nav_em__nav_desktop_sa_intl_tires_wheels_0_2_10_13
[2025-04-07T17:02:02.781+0000] {logger.py:11} INFO - ====== WebDriver manager ======
[2025-04-07T17:02:07.932+0000] {logger.py:11} INFO - Get LATEST chromedriver version for google-chrome
[2025-04-07T17:02:08.276+0000] {logger.py:11} INFO - Get LATEST chromedriver version for google-chrome
[2025-04-07T17:02:08.472+0000] {logger.py:11} INFO - Driver [/home/***/.wdm/drivers/chromedriver/linux64/135.0.7049.42/chromedriver-linux64/chromedriver] found in cache
[2025-04-07T17:05:12.111+0000] {test_crawl_list_product.py:220} ERROR - Error during scraping https://www.amazon.com/s?bbn=2562090011&rh=i%3Aspecialty-aps%2Cn%3A2562090011%2Cn%3A%2115690151%2Cn%3A15706571&s=date-desc-rank&ref_=nav_em__nav_desktop_sa_intl_tires_wheels_0_2_10_13: HTTPConnectionPool(host='localhost', port=56807): Read timed out. (read timeout=120)
[2025-04-07T17:05:59.382+0000] {test_crawl_list_product.py:191} INFO - Saved/Updated 0 products to /opt/***/csv/src_output/pt1_20250407/part1_data_Automotive_Tires & Wheels_20250407.csv
[2025-04-07T17:05:59.157+0000] {job.py:239} ERROR - Job heartbeat failed with error
Traceback (most recent call last):
  File "/home/airflow/.local/lib/python3.12/site-packages/sqlalchemy/engine/base.py", line 3371, in _wrap_pool_connect
    return fn()
           ^^^^
  File "/home/airflow/.local/lib/python3.12/site-packages/sqlalchemy/pool/base.py", line 327, in connect
    return _ConnectionFairy._checkout(self)
           ^^^^^^^^^^^^^^^^^^^^^^^^^^^^^^^^
  File "/home/airflow/.local/lib/python3.12/site-packages/sqlalchemy/pool/base.py", line 894, in _checkout
    fairy = _ConnectionRecord.checkout(pool)
            ^^^^^^^^^^^^^^^^^^^^^^^^^^^^^^^^
  File "/home/airflow/.local/lib/python3.12/site-packages/sqlalchemy/pool/base.py", line 493, in checkout
    rec = pool._do_get()
          ^^^^^^^^^^^^^^
  File "/home/airflow/.local/lib/python3.12/site-packages/sqlalchemy/pool/impl.py", line 256, in _do_get
    return self._create_connection()
           ^^^^^^^^^^^^^^^^^^^^^^^^^
  File "/home/airflow/.local/lib/python3.12/site-packages/sqlalchemy/pool/base.py", line 273, in _create_connection
    return _ConnectionRecord(self)
           ^^^^^^^^^^^^^^^^^^^^^^^
  File "/home/airflow/.local/lib/python3.12/site-packages/sqlalchemy/pool/base.py", line 388, in __init__
    self.__connect()
  File "/home/airflow/.local/lib/python3.12/site-packages/sqlalchemy/pool/base.py", line 690, in __connect
    with util.safe_reraise():
         ^^^^^^^^^^^^^^^^^^^
  File "/home/airflow/.local/lib/python3.12/site-packages/sqlalchemy/util/langhelpers.py", line 70, in __exit__
    compat.raise_(
  File "/home/airflow/.local/lib/python3.12/site-packages/sqlalchemy/util/compat.py", line 211, in raise_
    raise exception
  File "/home/airflow/.local/lib/python3.12/site-packages/sqlalchemy/pool/base.py", line 686, in __connect
    self.dbapi_connection = connection = pool._invoke_creator(self)
                                         ^^^^^^^^^^^^^^^^^^^^^^^^^^
  File "/home/airflow/.local/lib/python3.12/site-packages/sqlalchemy/engine/create.py", line 574, in connect
    return dialect.connect(*cargs, **cparams)
           ^^^^^^^^^^^^^^^^^^^^^^^^^^^^^^^^^^
  File "/home/airflow/.local/lib/python3.12/site-packages/sqlalchemy/engine/default.py", line 598, in connect
    return self.dbapi.connect(*cargs, **cparams)
           ^^^^^^^^^^^^^^^^^^^^^^^^^^^^^^^^^^^^^
  File "/home/airflow/.local/lib/python3.12/site-packages/psycopg2/__init__.py", line 122, in connect
    conn = _connect(dsn, connection_factory=connection_factory, **kwasync)
           ^^^^^^^^^^^^^^^^^^^^^^^^^^^^^^^^^^^^^^^^^^^^^^^^^^^^^^^^^^^^^^^
psycopg2.OperationalError: could not translate host name "postgres" to address: Temporary failure in name resolution


The above exception was the direct cause of the following exception:

Traceback (most recent call last):
  File "/home/airflow/.local/lib/python3.12/site-packages/airflow/jobs/job.py", line 207, in heartbeat
    self._merge_from(Job._fetch_from_db(self, session))
                     ^^^^^^^^^^^^^^^^^^^^^^^^^^^^^^^^^
  File "/home/airflow/.local/lib/python3.12/site-packages/airflow/api_internal/internal_api_call.py", line 166, in wrapper
    return func(*args, **kwargs)
           ^^^^^^^^^^^^^^^^^^^^^
  File "/home/airflow/.local/lib/python3.12/site-packages/airflow/utils/session.py", line 94, in wrapper
    return func(*args, **kwargs)
           ^^^^^^^^^^^^^^^^^^^^^
  File "/home/airflow/.local/lib/python3.12/site-packages/airflow/utils/retries.py", line 93, in wrapped_function
    for attempt in run_with_db_retries(max_retries=retries, logger=logger, **retry_kwargs):
                   ^^^^^^^^^^^^^^^^^^^^^^^^^^^^^^^^^^^^^^^^^^^^^^^^^^^^^^^^^^^^^^^^^^^^^^^
  File "/home/airflow/.local/lib/python3.12/site-packages/tenacity/__init__.py", line 443, in __iter__
    do = self.iter(retry_state=retry_state)
         ^^^^^^^^^^^^^^^^^^^^^^^^^^^^^^^^^^
  File "/home/airflow/.local/lib/python3.12/site-packages/tenacity/__init__.py", line 376, in iter
    result = action(retry_state)
             ^^^^^^^^^^^^^^^^^^^
  File "/home/airflow/.local/lib/python3.12/site-packages/tenacity/__init__.py", line 418, in exc_check
    raise retry_exc.reraise()
          ^^^^^^^^^^^^^^^^^^^
  File "/home/airflow/.local/lib/python3.12/site-packages/tenacity/__init__.py", line 185, in reraise
    raise self.last_attempt.result()
          ^^^^^^^^^^^^^^^^^^^^^^^^^^
  File "/usr/local/lib/python3.12/concurrent/futures/_base.py", line 449, in result
    return self.__get_result()
           ^^^^^^^^^^^^^^^^^^^
  File "/usr/local/lib/python3.12/concurrent/futures/_base.py", line 401, in __get_result
    raise self._exception
  File "/home/airflow/.local/lib/python3.12/site-packages/airflow/utils/retries.py", line 102, in wrapped_function
    return func(*args, **kwargs)
           ^^^^^^^^^^^^^^^^^^^^^
  File "/home/airflow/.local/lib/python3.12/site-packages/airflow/jobs/job.py", line 335, in _fetch_from_db
    session.merge(job)
  File "/home/airflow/.local/lib/python3.12/site-packages/sqlalchemy/orm/session.py", line 3056, in merge
    return self._merge(
           ^^^^^^^^^^^^
  File "/home/airflow/.local/lib/python3.12/site-packages/sqlalchemy/orm/session.py", line 3136, in _merge
    merged = self.get(
             ^^^^^^^^^
  File "/home/airflow/.local/lib/python3.12/site-packages/sqlalchemy/orm/session.py", line 2853, in get
    return self._get_impl(
           ^^^^^^^^^^^^^^^
  File "/home/airflow/.local/lib/python3.12/site-packages/sqlalchemy/orm/session.py", line 2975, in _get_impl
    return db_load_fn(
           ^^^^^^^^^^^
  File "/home/airflow/.local/lib/python3.12/site-packages/sqlalchemy/orm/loading.py", line 530, in load_on_pk_identity
    session.execute(
  File "/home/airflow/.local/lib/python3.12/site-packages/sqlalchemy/orm/session.py", line 1716, in execute
    conn = self._connection_for_bind(bind)
           ^^^^^^^^^^^^^^^^^^^^^^^^^^^^^^^
  File "/home/airflow/.local/lib/python3.12/site-packages/sqlalchemy/orm/session.py", line 1555, in _connection_for_bind
    return self._transaction._connection_for_bind(
           ^^^^^^^^^^^^^^^^^^^^^^^^^^^^^^^^^^^^^^^
  File "/home/airflow/.local/lib/python3.12/site-packages/sqlalchemy/orm/session.py", line 750, in _connection_for_bind
    conn = bind.connect()
           ^^^^^^^^^^^^^^
  File "/home/airflow/.local/lib/python3.12/site-packages/sqlalchemy/future/engine.py", line 412, in connect
    return super(Engine, self).connect()
           ^^^^^^^^^^^^^^^^^^^^^^^^^^^^^
  File "/home/airflow/.local/lib/python3.12/site-packages/sqlalchemy/engine/base.py", line 3325, in connect
    return self._connection_cls(self, close_with_result=close_with_result)
           ^^^^^^^^^^^^^^^^^^^^^^^^^^^^^^^^^^^^^^^^^^^^^^^^^^^^^^^^^^^^^^^
  File "/home/airflow/.local/lib/python3.12/site-packages/sqlalchemy/engine/base.py", line 96, in __init__
    else engine.raw_connection()
         ^^^^^^^^^^^^^^^^^^^^^^^
  File "/home/airflow/.local/lib/python3.12/site-packages/sqlalchemy/engine/base.py", line 3404, in raw_connection
    return self._wrap_pool_connect(self.pool.connect, _connection)
           ^^^^^^^^^^^^^^^^^^^^^^^^^^^^^^^^^^^^^^^^^^^^^^^^^^^^^^^
  File "/home/airflow/.local/lib/python3.12/site-packages/sqlalchemy/engine/base.py", line 3374, in _wrap_pool_connect
    Connection._handle_dbapi_exception_noconnection(
  File "/home/airflow/.local/lib/python3.12/site-packages/sqlalchemy/engine/base.py", line 2208, in _handle_dbapi_exception_noconnection
    util.raise_(
  File "/home/airflow/.local/lib/python3.12/site-packages/sqlalchemy/util/compat.py", line 211, in raise_
    raise exception
  File "/home/airflow/.local/lib/python3.12/site-packages/sqlalchemy/engine/base.py", line 3371, in _wrap_pool_connect
    return fn()
           ^^^^
  File "/home/airflow/.local/lib/python3.12/site-packages/sqlalchemy/pool/base.py", line 327, in connect
    return _ConnectionFairy._checkout(self)
           ^^^^^^^^^^^^^^^^^^^^^^^^^^^^^^^^
  File "/home/airflow/.local/lib/python3.12/site-packages/sqlalchemy/pool/base.py", line 894, in _checkout
    fairy = _ConnectionRecord.checkout(pool)
            ^^^^^^^^^^^^^^^^^^^^^^^^^^^^^^^^
  File "/home/airflow/.local/lib/python3.12/site-packages/sqlalchemy/pool/base.py", line 493, in checkout
    rec = pool._do_get()
          ^^^^^^^^^^^^^^
  File "/home/airflow/.local/lib/python3.12/site-packages/sqlalchemy/pool/impl.py", line 256, in _do_get
    return self._create_connection()
           ^^^^^^^^^^^^^^^^^^^^^^^^^
  File "/home/airflow/.local/lib/python3.12/site-packages/sqlalchemy/pool/base.py", line 273, in _create_connection
    return _ConnectionRecord(self)
           ^^^^^^^^^^^^^^^^^^^^^^^
  File "/home/airflow/.local/lib/python3.12/site-packages/sqlalchemy/pool/base.py", line 388, in __init__
    self.__connect()
  File "/home/airflow/.local/lib/python3.12/site-packages/sqlalchemy/pool/base.py", line 690, in __connect
    with util.safe_reraise():
         ^^^^^^^^^^^^^^^^^^^
  File "/home/airflow/.local/lib/python3.12/site-packages/sqlalchemy/util/langhelpers.py", line 70, in __exit__
    compat.raise_(
  File "/home/airflow/.local/lib/python3.12/site-packages/sqlalchemy/util/compat.py", line 211, in raise_
    raise exception
  File "/home/airflow/.local/lib/python3.12/site-packages/sqlalchemy/pool/base.py", line 686, in __connect
    self.dbapi_connection = connection = pool._invoke_creator(self)
                                         ^^^^^^^^^^^^^^^^^^^^^^^^^^
  File "/home/airflow/.local/lib/python3.12/site-packages/sqlalchemy/engine/create.py", line 574, in connect
    return dialect.connect(*cargs, **cparams)
           ^^^^^^^^^^^^^^^^^^^^^^^^^^^^^^^^^^
  File "/home/airflow/.local/lib/python3.12/site-packages/sqlalchemy/engine/default.py", line 598, in connect
    return self.dbapi.connect(*cargs, **cparams)
           ^^^^^^^^^^^^^^^^^^^^^^^^^^^^^^^^^^^^^
  File "/home/airflow/.local/lib/python3.12/site-packages/psycopg2/__init__.py", line 122, in connect
    conn = _connect(dsn, connection_factory=connection_factory, **kwasync)
           ^^^^^^^^^^^^^^^^^^^^^^^^^^^^^^^^^^^^^^^^^^^^^^^^^^^^^^^^^^^^^^^
sqlalchemy.exc.OperationalError: (psycopg2.OperationalError) could not translate host name "postgres" to address: Temporary failure in name resolution

(Background on this error at: https://sqlalche.me/e/14/e3q8)
[2025-04-07T17:05:59.542+0000] {job.py:254} ERROR - Job heartbeat failed with error. Scheduler is in unhealthy state
[2025-04-07T17:06:19.387+0000] {job.py:229} INFO - Heartbeat recovered after 218.36 seconds
[2025-04-07T17:06:26.510+0000] {python.py:240} INFO - Done. Returned value was: None
[2025-04-07T17:06:26.558+0000] {taskinstance.py:341} INFO - ::group::Post task execution logs
[2025-04-07T17:06:26.560+0000] {taskinstance.py:353} INFO - Marking task as SUCCESS. dag_id=scrape_amazon_dag, task_id=process_Tires___Wheels_11, run_id=manual__2025-04-07T17:01:09.892232+00:00, execution_date=20250407T170109, start_date=20250407T170153, end_date=20250407T170626
[2025-04-07T17:06:26.686+0000] {logging_mixin.py:190} INFO - Task instance in success state
[2025-04-07T17:06:26.688+0000] {logging_mixin.py:190} INFO -  Previous state of the Task instance: running
[2025-04-07T17:06:26.690+0000] {logging_mixin.py:190} INFO - Dag name:scrape_amazon_dag queued_at:2025-04-07 17:01:09.926255+00:00
[2025-04-07T17:06:26.692+0000] {logging_mixin.py:190} INFO - Task hostname:13b4251b7529 operator:PythonOperator
[2025-04-07T17:06:26.747+0000] {local_task_job_runner.py:266} INFO - Task exited with return code 0
[2025-04-07T17:06:26.798+0000] {taskinstance.py:3901} INFO - 0 downstream tasks scheduled from follow-on schedule check
[2025-04-07T17:06:26.822+0000] {local_task_job_runner.py:245} INFO - ::endgroup::
