[2025-04-08T04:03:01.934+0000] {local_task_job_runner.py:123} INFO - ::group::Pre task execution logs
[2025-04-08T04:03:02.475+0000] {taskinstance.py:2614} INFO - Dependencies all met for dep_context=non-requeueable deps ti=<TaskInstance: scrape_amazon_dag.process_Tires___Wheels_11 manual__2025-04-08T04:02:31.163432+00:00 [queued]>
[2025-04-08T04:03:02.581+0000] {taskinstance.py:2614} INFO - Dependencies all met for dep_context=requeueable deps ti=<TaskInstance: scrape_amazon_dag.process_Tires___Wheels_11 manual__2025-04-08T04:02:31.163432+00:00 [queued]>
[2025-04-08T04:03:02.591+0000] {taskinstance.py:2867} INFO - Starting attempt 1 of 2
[2025-04-08T04:03:04.131+0000] {taskinstance.py:2890} INFO - Executing <Task(PythonOperator): process_Tires___Wheels_11> on 2025-04-08 04:02:31.163432+00:00
[2025-04-08T04:03:04.178+0000] {warnings.py:112} WARNING - /home/***/.local/lib/python3.12/site-packages/***/task/task_runner/standard_task_runner.py:70: DeprecationWarning: This process (pid=5737) is multi-threaded, use of fork() may lead to deadlocks in the child.
  pid = os.fork()

[2025-04-08T04:03:04.222+0000] {standard_task_runner.py:72} INFO - Started process 6530 to run task
[2025-04-08T04:03:04.247+0000] {standard_task_runner.py:104} INFO - Running: ['***', 'tasks', 'run', 'scrape_amazon_dag', 'process_Tires___Wheels_11', 'manual__2025-04-08T04:02:31.163432+00:00', '--job-id', '163', '--raw', '--subdir', 'DAGS_FOLDER/test_crawl_list_product.py', '--cfg-path', '/tmp/tmp2v1fjgt9']
[2025-04-08T04:03:04.285+0000] {standard_task_runner.py:105} INFO - Job 163: Subtask process_Tires___Wheels_11
[2025-04-08T04:03:04.721+0000] {task_command.py:467} INFO - Running <TaskInstance: scrape_amazon_dag.process_Tires___Wheels_11 manual__2025-04-08T04:02:31.163432+00:00 [running]> on host 13b4251b7529
[2025-04-08T04:03:06.000+0000] {taskinstance.py:3134} INFO - Exporting env vars: AIRFLOW_CTX_DAG_OWNER='***' AIRFLOW_CTX_DAG_ID='scrape_amazon_dag' AIRFLOW_CTX_TASK_ID='process_Tires___Wheels_11' AIRFLOW_CTX_EXECUTION_DATE='2025-04-08T04:02:31.163432+00:00' AIRFLOW_CTX_TRY_NUMBER='1' AIRFLOW_CTX_DAG_RUN_ID='manual__2025-04-08T04:02:31.163432+00:00'
[2025-04-08T04:03:06.012+0000] {logging_mixin.py:190} INFO - Task instance is in running state
[2025-04-08T04:03:06.014+0000] {logging_mixin.py:190} INFO -  Previous state of the Task instance: queued
[2025-04-08T04:03:06.021+0000] {logging_mixin.py:190} INFO - Current task name:process_Tires___Wheels_11 state:running start_date:2025-04-08 04:03:02.484544+00:00
[2025-04-08T04:03:06.029+0000] {logging_mixin.py:190} INFO - Dag name:scrape_amazon_dag and current dag run status:running
[2025-04-08T04:03:06.034+0000] {taskinstance.py:732} INFO - ::endgroup::
[2025-04-08T04:03:06.057+0000] {test_crawl_list_product.py:228} INFO - Processing: Automotive/Tires & Wheels - https://www.amazon.com/s?bbn=2562090011&rh=i%3Aspecialty-aps%2Cn%3A2562090011%2Cn%3A%2115690151%2Cn%3A15706571&s=date-desc-rank&ref_=nav_em__nav_desktop_sa_intl_tires_wheels_0_2_10_13
[2025-04-08T04:03:06.838+0000] {test_crawl_list_product.py:46} INFO - Using user-agent: Mozilla/5.0 (Linux; Android 10; K) AppleWebKit/537.36 (KHTML, like Gecko) SamsungBrowser/27.0 Chrome/125.0.0.0 Mobile Safari/537.36
[2025-04-08T04:03:06.849+0000] {logger.py:11} INFO - ====== WebDriver manager ======
[2025-04-08T04:03:16.024+0000] {job.py:229} INFO - Heartbeat recovered after 21.89 seconds
[2025-04-08T04:03:22.334+0000] {logger.py:11} INFO - Get LATEST chromedriver version for google-chrome
[2025-04-08T04:03:35.937+0000] {job.py:229} INFO - Heartbeat recovered after 25.81 seconds
[2025-04-08T04:03:32.811+0000] {taskinstance.py:3313} ERROR - Task failed with exception
Traceback (most recent call last):
  File "/home/airflow/.local/lib/python3.12/site-packages/urllib3/connection.py", line 198, in _new_conn
    sock = connection.create_connection(
           ^^^^^^^^^^^^^^^^^^^^^^^^^^^^^
  File "/home/airflow/.local/lib/python3.12/site-packages/urllib3/util/connection.py", line 60, in create_connection
    for res in socket.getaddrinfo(host, port, family, socket.SOCK_STREAM):
               ^^^^^^^^^^^^^^^^^^^^^^^^^^^^^^^^^^^^^^^^^^^^^^^^^^^^^^^^^^
  File "/usr/local/lib/python3.12/socket.py", line 978, in getaddrinfo
    for res in _socket.getaddrinfo(host, port, family, type, proto, flags):
               ^^^^^^^^^^^^^^^^^^^^^^^^^^^^^^^^^^^^^^^^^^^^^^^^^^^^^^^^^^^
socket.gaierror: [Errno -3] Temporary failure in name resolution

The above exception was the direct cause of the following exception:

Traceback (most recent call last):
  File "/home/airflow/.local/lib/python3.12/site-packages/urllib3/connectionpool.py", line 787, in urlopen
    response = self._make_request(
               ^^^^^^^^^^^^^^^^^^^
  File "/home/airflow/.local/lib/python3.12/site-packages/urllib3/connectionpool.py", line 488, in _make_request
    raise new_e
  File "/home/airflow/.local/lib/python3.12/site-packages/urllib3/connectionpool.py", line 464, in _make_request
    self._validate_conn(conn)
  File "/home/airflow/.local/lib/python3.12/site-packages/urllib3/connectionpool.py", line 1093, in _validate_conn
    conn.connect()
  File "/home/airflow/.local/lib/python3.12/site-packages/urllib3/connection.py", line 704, in connect
    self.sock = sock = self._new_conn()
                       ^^^^^^^^^^^^^^^^
  File "/home/airflow/.local/lib/python3.12/site-packages/urllib3/connection.py", line 205, in _new_conn
    raise NameResolutionError(self.host, self, e) from e
urllib3.exceptions.NameResolutionError: <urllib3.connection.HTTPSConnection object at 0x7fb2171c1610>: Failed to resolve 'googlechromelabs.github.io' ([Errno -3] Temporary failure in name resolution)

The above exception was the direct cause of the following exception:

Traceback (most recent call last):
  File "/home/airflow/.local/lib/python3.12/site-packages/requests/adapters.py", line 667, in send
    resp = conn.urlopen(
           ^^^^^^^^^^^^^
  File "/home/airflow/.local/lib/python3.12/site-packages/urllib3/connectionpool.py", line 841, in urlopen
    retries = retries.increment(
              ^^^^^^^^^^^^^^^^^^
  File "/home/airflow/.local/lib/python3.12/site-packages/urllib3/util/retry.py", line 519, in increment
    raise MaxRetryError(_pool, url, reason) from reason  # type: ignore[arg-type]
    ^^^^^^^^^^^^^^^^^^^^^^^^^^^^^^^^^^^^^^^^^^^^^^^^^^^
urllib3.exceptions.MaxRetryError: HTTPSConnectionPool(host='googlechromelabs.github.io', port=443): Max retries exceeded with url: /chrome-for-testing/latest-patch-versions-per-build.json (Caused by NameResolutionError("<urllib3.connection.HTTPSConnection object at 0x7fb2171c1610>: Failed to resolve 'googlechromelabs.github.io' ([Errno -3] Temporary failure in name resolution)"))

During handling of the above exception, another exception occurred:

Traceback (most recent call last):
  File "/home/airflow/.local/lib/python3.12/site-packages/webdriver_manager/core/http.py", line 32, in get
    resp = requests.get(
           ^^^^^^^^^^^^^
  File "/home/airflow/.local/lib/python3.12/site-packages/requests/api.py", line 73, in get
    return request("get", url, params=params, **kwargs)
           ^^^^^^^^^^^^^^^^^^^^^^^^^^^^^^^^^^^^^^^^^^^^
  File "/home/airflow/.local/lib/python3.12/site-packages/requests/api.py", line 59, in request
    return session.request(method=method, url=url, **kwargs)
           ^^^^^^^^^^^^^^^^^^^^^^^^^^^^^^^^^^^^^^^^^^^^^^^^^
  File "/home/airflow/.local/lib/python3.12/site-packages/requests/sessions.py", line 589, in request
    resp = self.send(prep, **send_kwargs)
           ^^^^^^^^^^^^^^^^^^^^^^^^^^^^^^
  File "/home/airflow/.local/lib/python3.12/site-packages/requests/sessions.py", line 703, in send
    r = adapter.send(request, **kwargs)
        ^^^^^^^^^^^^^^^^^^^^^^^^^^^^^^^
  File "/home/airflow/.local/lib/python3.12/site-packages/requests/adapters.py", line 700, in send
    raise ConnectionError(e, request=request)
requests.exceptions.ConnectionError: HTTPSConnectionPool(host='googlechromelabs.github.io', port=443): Max retries exceeded with url: /chrome-for-testing/latest-patch-versions-per-build.json (Caused by NameResolutionError("<urllib3.connection.HTTPSConnection object at 0x7fb2171c1610>: Failed to resolve 'googlechromelabs.github.io' ([Errno -3] Temporary failure in name resolution)"))

During handling of the above exception, another exception occurred:

Traceback (most recent call last):
  File "/home/airflow/.local/lib/python3.12/site-packages/airflow/models/taskinstance.py", line 768, in _execute_task
    result = _execute_callable(context=context, **execute_callable_kwargs)
             ^^^^^^^^^^^^^^^^^^^^^^^^^^^^^^^^^^^^^^^^^^^^^^^^^^^^^^^^^^^^^
  File "/home/airflow/.local/lib/python3.12/site-packages/airflow/models/taskinstance.py", line 734, in _execute_callable
    return ExecutionCallableRunner(
           ^^^^^^^^^^^^^^^^^^^^^^^^
  File "/home/airflow/.local/lib/python3.12/site-packages/airflow/utils/operator_helpers.py", line 252, in run
    return self.func(*args, **kwargs)
           ^^^^^^^^^^^^^^^^^^^^^^^^^^
  File "/home/airflow/.local/lib/python3.12/site-packages/airflow/models/baseoperator.py", line 424, in wrapper
    return func(self, *args, **kwargs)
           ^^^^^^^^^^^^^^^^^^^^^^^^^^^
  File "/home/airflow/.local/lib/python3.12/site-packages/airflow/operators/python.py", line 238, in execute
    return_value = self.execute_callable()
                   ^^^^^^^^^^^^^^^^^^^^^^^
  File "/home/airflow/.local/lib/python3.12/site-packages/airflow/operators/python.py", line 256, in execute_callable
    return runner.run(*self.op_args, **self.op_kwargs)
           ^^^^^^^^^^^^^^^^^^^^^^^^^^^^^^^^^^^^^^^^^^^
  File "/home/airflow/.local/lib/python3.12/site-packages/airflow/utils/operator_helpers.py", line 252, in run
    return self.func(*args, **kwargs)
           ^^^^^^^^^^^^^^^^^^^^^^^^^^
  File "/opt/airflow/dags/test_crawl_list_product.py", line 229, in scrape_department
    scraper = AmazonScraper()
              ^^^^^^^^^^^^^^^
  File "/opt/airflow/dags/test_crawl_list_product.py", line 41, in __init__
    self.setup_driver()
  File "/opt/airflow/dags/test_crawl_list_product.py", line 57, in setup_driver
    service = ChromeService(ChromeDriverManager().install())
                            ^^^^^^^^^^^^^^^^^^^^^^^^^^^^^^^
  File "/home/airflow/.local/lib/python3.12/site-packages/webdriver_manager/chrome.py", line 40, in install
    driver_path = self._get_driver_binary_path(self.driver)
                  ^^^^^^^^^^^^^^^^^^^^^^^^^^^^^^^^^^^^^^^^^
  File "/home/airflow/.local/lib/python3.12/site-packages/webdriver_manager/core/manager.py", line 35, in _get_driver_binary_path
    binary_path = self._cache_manager.find_driver(driver)
                  ^^^^^^^^^^^^^^^^^^^^^^^^^^^^^^^^^^^^^^^
  File "/home/airflow/.local/lib/python3.12/site-packages/webdriver_manager/core/driver_cache.py", line 107, in find_driver
    driver_version = self.get_cache_key_driver_version(driver)
                     ^^^^^^^^^^^^^^^^^^^^^^^^^^^^^^^^^^^^^^^^^
  File "/home/airflow/.local/lib/python3.12/site-packages/webdriver_manager/core/driver_cache.py", line 154, in get_cache_key_driver_version
    return driver.get_driver_version_to_download()
           ^^^^^^^^^^^^^^^^^^^^^^^^^^^^^^^^^^^^^^^
  File "/home/airflow/.local/lib/python3.12/site-packages/webdriver_manager/core/driver.py", line 48, in get_driver_version_to_download
    return self.get_latest_release_version()
           ^^^^^^^^^^^^^^^^^^^^^^^^^^^^^^^^^
  File "/home/airflow/.local/lib/python3.12/site-packages/webdriver_manager/drivers/chrome.py", line 59, in get_latest_release_version
    response = self._http_client.get(url)
               ^^^^^^^^^^^^^^^^^^^^^^^^^^
  File "/home/airflow/.local/lib/python3.12/site-packages/webdriver_manager/core/http.py", line 35, in get
    raise exceptions.ConnectionError(f"Could not reach host. Are you offline?")
requests.exceptions.ConnectionError: Could not reach host. Are you offline?
[2025-04-08T04:03:36.896+0000] {logging_mixin.py:190} INFO - Task instance in failure state
[2025-04-08T04:03:36.908+0000] {logging_mixin.py:190} INFO - Task start:2025-04-08 04:03:02.484544+00:00 end:2025-04-08 04:03:36.891237+00:00 duration:34.406693
[2025-04-08T04:03:36.924+0000] {logging_mixin.py:190} INFO - Task:<Task(PythonOperator): process_Tires___Wheels_11> dag:<DAG: scrape_amazon_dag> dagrun:<DagRun scrape_amazon_dag @ 2025-04-08 04:02:31.163432+00:00: manual__2025-04-08T04:02:31.163432+00:00, state:running, queued_at: 2025-04-08 04:02:31.265789+00:00. externally triggered: True>
[2025-04-08T04:03:36.931+0000] {logging_mixin.py:190} INFO - Failure caused by Could not reach host. Are you offline?
[2025-04-08T04:03:36.959+0000] {taskinstance.py:1226} INFO - Marking task as UP_FOR_RETRY. dag_id=scrape_amazon_dag, task_id=process_Tires___Wheels_11, run_id=manual__2025-04-08T04:02:31.163432+00:00, execution_date=20250408T040231, start_date=20250408T040302, end_date=20250408T040336
[2025-04-08T04:03:37.188+0000] {taskinstance.py:341} INFO - ::group::Post task execution logs
[2025-04-08T04:03:37.196+0000] {standard_task_runner.py:124} ERROR - Failed to execute job 163 for task process_Tires___Wheels_11 (Could not reach host. Are you offline?; 6530)
Traceback (most recent call last):
  File "/home/airflow/.local/lib/python3.12/site-packages/urllib3/connection.py", line 198, in _new_conn
    sock = connection.create_connection(
           ^^^^^^^^^^^^^^^^^^^^^^^^^^^^^
  File "/home/airflow/.local/lib/python3.12/site-packages/urllib3/util/connection.py", line 60, in create_connection
    for res in socket.getaddrinfo(host, port, family, socket.SOCK_STREAM):
               ^^^^^^^^^^^^^^^^^^^^^^^^^^^^^^^^^^^^^^^^^^^^^^^^^^^^^^^^^^
  File "/usr/local/lib/python3.12/socket.py", line 978, in getaddrinfo
    for res in _socket.getaddrinfo(host, port, family, type, proto, flags):
               ^^^^^^^^^^^^^^^^^^^^^^^^^^^^^^^^^^^^^^^^^^^^^^^^^^^^^^^^^^^
socket.gaierror: [Errno -3] Temporary failure in name resolution

The above exception was the direct cause of the following exception:

Traceback (most recent call last):
  File "/home/airflow/.local/lib/python3.12/site-packages/urllib3/connectionpool.py", line 787, in urlopen
    response = self._make_request(
               ^^^^^^^^^^^^^^^^^^^
  File "/home/airflow/.local/lib/python3.12/site-packages/urllib3/connectionpool.py", line 488, in _make_request
    raise new_e
  File "/home/airflow/.local/lib/python3.12/site-packages/urllib3/connectionpool.py", line 464, in _make_request
    self._validate_conn(conn)
  File "/home/airflow/.local/lib/python3.12/site-packages/urllib3/connectionpool.py", line 1093, in _validate_conn
    conn.connect()
  File "/home/airflow/.local/lib/python3.12/site-packages/urllib3/connection.py", line 704, in connect
    self.sock = sock = self._new_conn()
                       ^^^^^^^^^^^^^^^^
  File "/home/airflow/.local/lib/python3.12/site-packages/urllib3/connection.py", line 205, in _new_conn
    raise NameResolutionError(self.host, self, e) from e
urllib3.exceptions.NameResolutionError: <urllib3.connection.HTTPSConnection object at 0x7fb2171c1610>: Failed to resolve 'googlechromelabs.github.io' ([Errno -3] Temporary failure in name resolution)

The above exception was the direct cause of the following exception:

Traceback (most recent call last):
  File "/home/airflow/.local/lib/python3.12/site-packages/requests/adapters.py", line 667, in send
    resp = conn.urlopen(
           ^^^^^^^^^^^^^
  File "/home/airflow/.local/lib/python3.12/site-packages/urllib3/connectionpool.py", line 841, in urlopen
    retries = retries.increment(
              ^^^^^^^^^^^^^^^^^^
  File "/home/airflow/.local/lib/python3.12/site-packages/urllib3/util/retry.py", line 519, in increment
    raise MaxRetryError(_pool, url, reason) from reason  # type: ignore[arg-type]
    ^^^^^^^^^^^^^^^^^^^^^^^^^^^^^^^^^^^^^^^^^^^^^^^^^^^
urllib3.exceptions.MaxRetryError: HTTPSConnectionPool(host='googlechromelabs.github.io', port=443): Max retries exceeded with url: /chrome-for-testing/latest-patch-versions-per-build.json (Caused by NameResolutionError("<urllib3.connection.HTTPSConnection object at 0x7fb2171c1610>: Failed to resolve 'googlechromelabs.github.io' ([Errno -3] Temporary failure in name resolution)"))

During handling of the above exception, another exception occurred:

Traceback (most recent call last):
  File "/home/airflow/.local/lib/python3.12/site-packages/webdriver_manager/core/http.py", line 32, in get
    resp = requests.get(
           ^^^^^^^^^^^^^
  File "/home/airflow/.local/lib/python3.12/site-packages/requests/api.py", line 73, in get
    return request("get", url, params=params, **kwargs)
           ^^^^^^^^^^^^^^^^^^^^^^^^^^^^^^^^^^^^^^^^^^^^
  File "/home/airflow/.local/lib/python3.12/site-packages/requests/api.py", line 59, in request
    return session.request(method=method, url=url, **kwargs)
           ^^^^^^^^^^^^^^^^^^^^^^^^^^^^^^^^^^^^^^^^^^^^^^^^^
  File "/home/airflow/.local/lib/python3.12/site-packages/requests/sessions.py", line 589, in request
    resp = self.send(prep, **send_kwargs)
           ^^^^^^^^^^^^^^^^^^^^^^^^^^^^^^
  File "/home/airflow/.local/lib/python3.12/site-packages/requests/sessions.py", line 703, in send
    r = adapter.send(request, **kwargs)
        ^^^^^^^^^^^^^^^^^^^^^^^^^^^^^^^
  File "/home/airflow/.local/lib/python3.12/site-packages/requests/adapters.py", line 700, in send
    raise ConnectionError(e, request=request)
requests.exceptions.ConnectionError: HTTPSConnectionPool(host='googlechromelabs.github.io', port=443): Max retries exceeded with url: /chrome-for-testing/latest-patch-versions-per-build.json (Caused by NameResolutionError("<urllib3.connection.HTTPSConnection object at 0x7fb2171c1610>: Failed to resolve 'googlechromelabs.github.io' ([Errno -3] Temporary failure in name resolution)"))

During handling of the above exception, another exception occurred:

Traceback (most recent call last):
  File "/home/airflow/.local/lib/python3.12/site-packages/airflow/task/task_runner/standard_task_runner.py", line 117, in _start_by_fork
    ret = args.func(args, dag=self.dag)
          ^^^^^^^^^^^^^^^^^^^^^^^^^^^^^
  File "/home/airflow/.local/lib/python3.12/site-packages/airflow/cli/cli_config.py", line 49, in command
    return func(*args, **kwargs)
           ^^^^^^^^^^^^^^^^^^^^^
  File "/home/airflow/.local/lib/python3.12/site-packages/airflow/utils/cli.py", line 116, in wrapper
    return f(*args, **kwargs)
           ^^^^^^^^^^^^^^^^^^
  File "/home/airflow/.local/lib/python3.12/site-packages/airflow/cli/commands/task_command.py", line 483, in task_run
    task_return_code = _run_task_by_selected_method(args, _dag, ti)
                       ^^^^^^^^^^^^^^^^^^^^^^^^^^^^^^^^^^^^^^^^^^^^
  File "/home/airflow/.local/lib/python3.12/site-packages/airflow/cli/commands/task_command.py", line 256, in _run_task_by_selected_method
    return _run_raw_task(args, ti)
           ^^^^^^^^^^^^^^^^^^^^^^^
  File "/home/airflow/.local/lib/python3.12/site-packages/airflow/cli/commands/task_command.py", line 341, in _run_raw_task
    return ti._run_raw_task(
           ^^^^^^^^^^^^^^^^^
  File "/home/airflow/.local/lib/python3.12/site-packages/airflow/utils/session.py", line 97, in wrapper
    return func(*args, session=session, **kwargs)
           ^^^^^^^^^^^^^^^^^^^^^^^^^^^^^^^^^^^^^^
  File "/home/airflow/.local/lib/python3.12/site-packages/airflow/models/taskinstance.py", line 3006, in _run_raw_task
    return _run_raw_task(
           ^^^^^^^^^^^^^^
  File "/home/airflow/.local/lib/python3.12/site-packages/airflow/models/taskinstance.py", line 274, in _run_raw_task
    TaskInstance._execute_task_with_callbacks(
  File "/home/airflow/.local/lib/python3.12/site-packages/airflow/models/taskinstance.py", line 3161, in _execute_task_with_callbacks
    result = self._execute_task(context, task_orig)
             ^^^^^^^^^^^^^^^^^^^^^^^^^^^^^^^^^^^^^^
  File "/home/airflow/.local/lib/python3.12/site-packages/airflow/models/taskinstance.py", line 3185, in _execute_task
    return _execute_task(self, context, task_orig)
           ^^^^^^^^^^^^^^^^^^^^^^^^^^^^^^^^^^^^^^^
  File "/home/airflow/.local/lib/python3.12/site-packages/airflow/models/taskinstance.py", line 768, in _execute_task
    result = _execute_callable(context=context, **execute_callable_kwargs)
             ^^^^^^^^^^^^^^^^^^^^^^^^^^^^^^^^^^^^^^^^^^^^^^^^^^^^^^^^^^^^^
  File "/home/airflow/.local/lib/python3.12/site-packages/airflow/models/taskinstance.py", line 734, in _execute_callable
    return ExecutionCallableRunner(
           ^^^^^^^^^^^^^^^^^^^^^^^^
  File "/home/airflow/.local/lib/python3.12/site-packages/airflow/utils/operator_helpers.py", line 252, in run
    return self.func(*args, **kwargs)
           ^^^^^^^^^^^^^^^^^^^^^^^^^^
  File "/home/airflow/.local/lib/python3.12/site-packages/airflow/models/baseoperator.py", line 424, in wrapper
    return func(self, *args, **kwargs)
           ^^^^^^^^^^^^^^^^^^^^^^^^^^^
  File "/home/airflow/.local/lib/python3.12/site-packages/airflow/operators/python.py", line 238, in execute
    return_value = self.execute_callable()
                   ^^^^^^^^^^^^^^^^^^^^^^^
  File "/home/airflow/.local/lib/python3.12/site-packages/airflow/operators/python.py", line 256, in execute_callable
    return runner.run(*self.op_args, **self.op_kwargs)
           ^^^^^^^^^^^^^^^^^^^^^^^^^^^^^^^^^^^^^^^^^^^
  File "/home/airflow/.local/lib/python3.12/site-packages/airflow/utils/operator_helpers.py", line 252, in run
    return self.func(*args, **kwargs)
           ^^^^^^^^^^^^^^^^^^^^^^^^^^
  File "/opt/airflow/dags/test_crawl_list_product.py", line 229, in scrape_department
    scraper = AmazonScraper()
              ^^^^^^^^^^^^^^^
  File "/opt/airflow/dags/test_crawl_list_product.py", line 41, in __init__
    self.setup_driver()
  File "/opt/airflow/dags/test_crawl_list_product.py", line 57, in setup_driver
    service = ChromeService(ChromeDriverManager().install())
                            ^^^^^^^^^^^^^^^^^^^^^^^^^^^^^^^
  File "/home/airflow/.local/lib/python3.12/site-packages/webdriver_manager/chrome.py", line 40, in install
    driver_path = self._get_driver_binary_path(self.driver)
                  ^^^^^^^^^^^^^^^^^^^^^^^^^^^^^^^^^^^^^^^^^
  File "/home/airflow/.local/lib/python3.12/site-packages/webdriver_manager/core/manager.py", line 35, in _get_driver_binary_path
    binary_path = self._cache_manager.find_driver(driver)
                  ^^^^^^^^^^^^^^^^^^^^^^^^^^^^^^^^^^^^^^^
  File "/home/airflow/.local/lib/python3.12/site-packages/webdriver_manager/core/driver_cache.py", line 107, in find_driver
    driver_version = self.get_cache_key_driver_version(driver)
                     ^^^^^^^^^^^^^^^^^^^^^^^^^^^^^^^^^^^^^^^^^
  File "/home/airflow/.local/lib/python3.12/site-packages/webdriver_manager/core/driver_cache.py", line 154, in get_cache_key_driver_version
    return driver.get_driver_version_to_download()
           ^^^^^^^^^^^^^^^^^^^^^^^^^^^^^^^^^^^^^^^
  File "/home/airflow/.local/lib/python3.12/site-packages/webdriver_manager/core/driver.py", line 48, in get_driver_version_to_download
    return self.get_latest_release_version()
           ^^^^^^^^^^^^^^^^^^^^^^^^^^^^^^^^^
  File "/home/airflow/.local/lib/python3.12/site-packages/webdriver_manager/drivers/chrome.py", line 59, in get_latest_release_version
    response = self._http_client.get(url)
               ^^^^^^^^^^^^^^^^^^^^^^^^^^
  File "/home/airflow/.local/lib/python3.12/site-packages/webdriver_manager/core/http.py", line 35, in get
    raise exceptions.ConnectionError(f"Could not reach host. Are you offline?")
requests.exceptions.ConnectionError: Could not reach host. Are you offline?
[2025-04-08T04:03:37.301+0000] {local_task_job_runner.py:266} INFO - Task exited with return code 1
[2025-04-08T04:03:37.360+0000] {taskinstance.py:3901} INFO - 0 downstream tasks scheduled from follow-on schedule check
[2025-04-08T04:03:37.372+0000] {local_task_job_runner.py:245} INFO - ::endgroup::
